Workbook

Sheet 🏁 Fahrerwertung
A1: 🏁 2017 — FAHRERWERTUNG
A2: Position eintragen · Punkte 25/18/15/12/10/8/6/4/2/1 · "DNF"/leer = nicht beendet · Pfirsich = SUB-Strecke · 20 Rennen
A4: # | B4: Fahrer | C4: Team | D4: R1 | E4: R2 | F4: R3 | G4: R4 | H4: R5 | I4: R6 | J4: R7 | K4: R8 | L4: R9 | M4: R10 | N4: R11 | O4: R12 | P4: R13 | Q4: R14 | R4: R15 | S4: R16 | T4: R17 | U4: R18 | V4: R19 | W4: R20 | X4: Punkte | Y4: Pos
D5: Melbourne | E5: Shanghai | F5: Bahrain | G5: Valencia | H5: Barcelona | I5: Zandvoort | J5: Fuji | K5: Montreal | L5: Spielberg | M5: Silverstone | N5: Hungaroring | O5: Spa | P5: Monza | Q5: Singapur | R5: Mugello | S5: Suzuka | T5: COTA | U5: Mexico | V5: Interlagos | W5: Indianapolis
A6: 1 | B6: S. Vandoorne | C6: McLaren-Honda | D6: 14 | E6: DNF | F6: 13 | G6: 10 | H6: 9 | I6: 16 | J6: 8 | K6: 17 | L6: 11 | M6: 12 | N6: 8 | O6: 14 | P6: 18 | Q6: 7 | R6: 10 | S6: 14 | T6: DNF | U6: 15 | V6: 16 | W6: 14 | X6: =COUNTIF(D6:W6,1)*25+COUNTIF(D6:W6,2)*18+COUNTIF(D6:W6,3)*15+COUNTIF(D6:W6,4)*12+COUNTIF(D6:W6,5)*10+COUNTIF(D6:W6,6)*8+COUNTIF(D6:W6,7)*6+COUNTIF(D6:W6,8)*4+COUNTIF(D6:W6,9)*2+COUNTIF(D6:W6,10)*1 -> 18 | Y6: =IF(X6=0,"-",RANK(X6,$X$6:$X$25,0)) -> 15
A7: 2 | B7: SABANOV | C7: McLaren-Honda | D7: 8 | E7: 6 | F7: 11 | G7: DNF | H7: 10 | I7: 7 | J7: DNF | K7: 15 | L7: 10 | M7: 14 | N7: 9 | O7: 11 | P7: 16 | Q7: 3 | R7: DNF | S7: 11 | T7: DNF | U7: 13 | V7: 12 | W7: DNF | X7: =COUNTIF(D7:W7,1)*25+COUNTIF(D7:W7,2)*18+COUNTIF(D7:W7,3)*15+COUNTIF(D7:W7,4)*12+COUNTIF(D7:W7,5)*10+COUNTIF(D7:W7,6)*8+COUNTIF(D7:W7,7)*6+COUNTIF(D7:W7,8)*4+COUNTIF(D7:W7,9)*2+COUNTIF(D7:W7,10)*1 -> 37 | Y7: =IF(X7=0,"-",RANK(X7,$X$6:$X$25,0)) -> 13
A8: 3 | B8: L. Hamilton | C8: Mercedes | D8: 3 | E8: 1 | F8: 2 | G8: 4 | H8: 2 | I8: 2 | J8: 1 | K8: 6 | L8: 6 | M8: 2 | N8: 3 | O8: 1 | P8: 1 | Q8: 1 | R8: 3 | S8: 5 | T8: 4 | U8: 2 | V8: 6 | W8: 4 | X8: =COUNTIF(D8:W8,1)*25+COUNTIF(D8:W8,2)*18+COUNTIF(D8:W8,3)*15+COUNTIF(D8:W8,4)*12+COUNTIF(D8:W8,5)*10+COUNTIF(D8:W8,6)*8+COUNTIF(D8:W8,7)*6+COUNTIF(D8:W8,8)*4+COUNTIF(D8:W8,9)*2+COUNTIF(D8:W8,10)*1 -> 330 | Y8: =IF(X8=0,"-",RANK(X8,$X$6:$X$25,0)) -> 2
A9: 4 | B9: V. Bottas | C9: Mercedes | D9: 5 | E9: 7 | F9: 6 | G9: 1 | H9: DNF | I9: 4 | J9: 6 | K9: 1 | L9: 4 | M9: 3 | N9: 5 | O9: 3 | P9: 2 | Q9: 4 | R9: DNF | S9: 2 | T9: 5 | U9: 4 | V9: 7 | W9: 5 | X9: =COUNTIF(D9:W9,1)*25+COUNTIF(D9:W9,2)*18+COUNTIF(D9:W9,3)*15+COUNTIF(D9:W9,4)*12+COUNTIF(D9:W9,5)*10+COUNTIF(D9:W9,6)*8+COUNTIF(D9:W9,7)*6+COUNTIF(D9:W9,8)*4+COUNTIF(D9:W9,9)*2+COUNTIF(D9:W9,10)*1 -> 232 | Y9: =IF(X9=0,"-",RANK(X9,$X$6:$X$25,0)) -> 4
A10: 5 | B10: S. Vettel | C10: Ferrari | D10: 1 | E10: 2 | F10: 4 | G10: 2 | H10: 3 | I10: 1 | J10: 7 | K10: 3 | L10: 2 | M10: 1 | N10: 1 | O10: 2 | P10: 5 | Q10: DNF | R10: 4 | S10: DNF | T10: 1 | U10: 3 | V10: 1 | W10: 3 | X10: =COUNTIF(D10:W10,1)*25+COUNTIF(D10:W10,2)*18+COUNTIF(D10:W10,3)*15+COUNTIF(D10:W10,4)*12+COUNTIF(D10:W10,5)*10+COUNTIF(D10:W10,6)*8+COUNTIF(D10:W10,7)*6+COUNTIF(D10:W10,8)*4+COUNTIF(D10:W10,9)*2+COUNTIF(D10:W10,10)*1 -> 322 | Y10: =IF(X10=0,"-",RANK(X10,$X$6:$X$25,0)) -> 3
A11: 6 | B11: F. Alonso | C11: Ferrari | D11: 2 | E11: 3 | F11: 1 | G11: 3 | H11: 1 | I11: 3 | J11: DNF | K11: 2 | L11: 1 | M11: 5 | N11: 2 | O11: 4 | P11: 3 | Q11: 2 | R11: DNF | S11: 1 | T11: 2 | U11: 1 | V11: 2 | W11: 2 | X11: =COUNTIF(D11:W11,1)*25+COUNTIF(D11:W11,2)*18+COUNTIF(D11:W11,3)*15+COUNTIF(D11:W11,4)*12+COUNTIF(D11:W11,5)*10+COUNTIF(D11:W11,6)*8+COUNTIF(D11:W11,7)*6+COUNTIF(D11:W11,8)*4+COUNTIF(D11:W11,9)*2+COUNTIF(D11:W11,10)*1 -> 333 | Y11: =IF(X11=0,"-",RANK(X11,$X$6:$X$25,0)) -> 1
A12: 7 | B12: D. Ricciardo | C12: Red Bull-TAG Heuer | D12: 7 | E12: 5 | F12: 3 | G12: DNF | H12: DNF | I12: 6 | J12: 2 | K12: 7 | L12: 3 | M12: 4 | N12: DNF | O12: 7 | P12: 6 | Q12: 8 | R12: 2 | S12: 4 | T12: DNF | U12: DNF | V12: 1 | W12: DNF | X12: =COUNTIF(D12:W12,1)*25+COUNTIF(D12:W12,2)*18+COUNTIF(D12:W12,3)*15+COUNTIF(D12:W12,4)*12+COUNTIF(D12:W12,5)*10+COUNTIF(D12:W12,6)*8+COUNTIF(D12:W12,7)*6+COUNTIF(D12:W12,8)*4+COUNTIF(D12:W12,9)*2+COUNTIF(D12:W12,10)*1 -> 163 | Y12: =IF(X12=0,"-",RANK(X12,$X$6:$X$25,0)) -> 6
A13: 8 | B13: M. Verstappen | C13: Red Bull-TAG Heuer | D13: 4 | E13: 4 | F13: DNF | G13: 5 | H13: DNF | I13: 5 | J13: DNF | K13: DNF | L13: DNF | M13: 6 | N13: 4 | O13: DNF | P13: 4 | Q13: DNF | R13: 1 | S13: 3 | T13: 3 | U13: 3 | V13: 5 | W13: 1 | X13: =COUNTIF(D13:W13,1)*25+COUNTIF(D13:W13,2)*18+COUNTIF(D13:W13,3)*15+COUNTIF(D13:W13,4)*12+COUNTIF(D13:W13,5)*10+COUNTIF(D13:W13,6)*8+COUNTIF(D13:W13,7)*6+COUNTIF(D13:W13,8)*4+COUNTIF(D13:W13,9)*2+COUNTIF(D13:W13,10)*1 -> 181 | Y13: =IF(X13=0,"-",RANK(X13,$X$6:$X$25,0)) -> 5
A14: 9 | B14: S. Pérez | C14: Force India-Mercedes | D14: 9 | E14: DNF | F14: 5 | G14: 9 | H14: 4 | I14: 8 | J14: 9 | K14: 8 | L14: 9 | O14: 8 | P14: 8 | Q14: 9 | R14: 9 | S14: 7 | T14: 9 | U14: 5 | V14: 9 | W14: 8 | X14: =COUNTIF(D14:W14,1)*25+COUNTIF(D14:W14,2)*18+COUNTIF(D14:W14,3)*15+COUNTIF(D14:W14,4)*12+COUNTIF(D14:W14,5)*10+COUNTIF(D14:W14,6)*8+COUNTIF(D14:W14,7)*6+COUNTIF(D14:W14,8)*4+COUNTIF(D14:W14,9)*2+COUNTIF(D14:W14,10)*1 -> 74 | Y14: =IF(X14=0,"-",RANK(X14,$X$6:$X$25,0)) -> 9
A15: 10 | B15: E. Ocon | C15: Force India-Mercedes | D15: 6 | E15: DNF | F15: DNF | G15: 6 | H15: 8 | I15: 10 | J15: 5 | K15: 9 | L15: 7 | M15: 8 | R15: 5 | S15: 9 | T15: 6 | V15: 8 | W15: 6 | X15: =COUNTIF(D15:W15,1)*25+COUNTIF(D15:W15,2)*18+COUNTIF(D15:W15,3)*15+COUNTIF(D15:W15,4)*12+COUNTIF(D15:W15,5)*10+COUNTIF(D15:W15,6)*8+COUNTIF(D15:W15,7)*6+COUNTIF(D15:W15,8)*4+COUNTIF(D15:W15,9)*2+COUNTIF(D15:W15,10)*1 -> 75 | Y15: =IF(X15=0,"-",RANK(X15,$X$6:$X$25,0)) -> 8
A16: 11 | B16: F. Massa | C16: Williams-Mercedes | E16: 8 | H16: 5 | J16: 3 | L16: 8 | N16: 7 | O16: 6 | P16: 7 | R16: 8 | S16: 6 | T16: 7 | U16: 6 | V16: 10 | W16: 9 | X16: =COUNTIF(D16:W16,1)*25+COUNTIF(D16:W16,2)*18+COUNTIF(D16:W16,3)*15+COUNTIF(D16:W16,4)*12+COUNTIF(D16:W16,5)*10+COUNTIF(D16:W16,6)*8+COUNTIF(D16:W16,7)*6+COUNTIF(D16:W16,8)*4+COUNTIF(D16:W16,9)*2+COUNTIF(D16:W16,10)*1 -> 82 | Y16: =IF(X16=0,"-",RANK(X16,$X$6:$X$25,0)) -> 7
A17: 12 | B17: L. Stroll | C17: Williams-Mercedes | D17: 10 | I17: 9 | J17: 4 | K17: 10 | M17: 7 | N17: 10 | O17: 9 | Q17: 5 | S17: 8 | T17: 8 | X17: =COUNTIF(D17:W17,1)*25+COUNTIF(D17:W17,2)*18+COUNTIF(D17:W17,3)*15+COUNTIF(D17:W17,4)*12+COUNTIF(D17:W17,5)*10+COUNTIF(D17:W17,6)*8+COUNTIF(D17:W17,7)*6+COUNTIF(D17:W17,8)*4+COUNTIF(D17:W17,9)*2+COUNTIF(D17:W17,10)*1 -> 43 | Y17: =IF(X17=0,"-",RANK(X17,$X$6:$X$25,0)) -> 12
A18: 13 | B18: N. Hülkenberg | C18: Renault | E18: 9 | G18: 8 | K18: 5 | P18: 9 | Q18: 6 | U18: 10 | V18: 4 | W18: 7 | X18: =COUNTIF(D18:W18,1)*25+COUNTIF(D18:W18,2)*18+COUNTIF(D18:W18,3)*15+COUNTIF(D18:W18,4)*12+COUNTIF(D18:W18,5)*10+COUNTIF(D18:W18,6)*8+COUNTIF(D18:W18,7)*6+COUNTIF(D18:W18,8)*4+COUNTIF(D18:W18,9)*2+COUNTIF(D18:W18,10)*1 -> 45 | Y18: =IF(X18=0,"-",RANK(X18,$X$6:$X$25,0)) -> 11
A19: 14 | B19: N. Rosberg | C19: Renault | G19: 7 | H19: 6 | J19: 10 | K19: 4 | L19: 5 | R19: 6 | S19: 10 | V19: 3 | X19: =COUNTIF(D19:W19,1)*25+COUNTIF(D19:W19,2)*18+COUNTIF(D19:W19,3)*15+COUNTIF(D19:W19,4)*12+COUNTIF(D19:W19,5)*10+COUNTIF(D19:W19,6)*8+COUNTIF(D19:W19,7)*6+COUNTIF(D19:W19,8)*4+COUNTIF(D19:W19,9)*2+COUNTIF(D19:W19,10)*1 -> 61 | Y19: =IF(X19=0,"-",RANK(X19,$X$6:$X$25,0)) -> 10
A20: 15 | B20: C. Sainz | C20: Toro Rosso-Renault | E20: 10 | M20: 9 | N20: 6 | O20: 5 | P20: 10 | R20: 7 | U20: 7 | W20: 10 | X20: =COUNTIF(D20:W20,1)*25+COUNTIF(D20:W20,2)*18+COUNTIF(D20:W20,3)*15+COUNTIF(D20:W20,4)*12+COUNTIF(D20:W20,5)*10+COUNTIF(D20:W20,6)*8+COUNTIF(D20:W20,7)*6+COUNTIF(D20:W20,8)*4+COUNTIF(D20:W20,9)*2+COUNTIF(D20:W20,10)*1 -> 35 | Y20: =IF(X20=0,"-",RANK(X20,$X$6:$X$25,0)) -> 14
A21: 16 | B21: D. Kvyat | C21: Toro Rosso-Renault | H21: 7 | M21: 10 | O21: 10 | Q21: 10 | X21: =COUNTIF(D21:W21,1)*25+COUNTIF(D21:W21,2)*18+COUNTIF(D21:W21,3)*15+COUNTIF(D21:W21,4)*12+COUNTIF(D21:W21,5)*10+COUNTIF(D21:W21,6)*8+COUNTIF(D21:W21,7)*6+COUNTIF(D21:W21,8)*4+COUNTIF(D21:W21,9)*2+COUNTIF(D21:W21,10)*1 -> 9 | Y21: =IF(X21=0,"-",RANK(X21,$X$6:$X$25,0)) -> 16
A22: 17 | B22: R. Grosjean | C22: Haas-Ferrari | U22: 8 | X22: =COUNTIF(D22:W22,1)*25+COUNTIF(D22:W22,2)*18+COUNTIF(D22:W22,3)*15+COUNTIF(D22:W22,4)*12+COUNTIF(D22:W22,5)*10+COUNTIF(D22:W22,6)*8+COUNTIF(D22:W22,7)*6+COUNTIF(D22:W22,8)*4+COUNTIF(D22:W22,9)*2+COUNTIF(D22:W22,10)*1 -> 4 | Y22: =IF(X22=0,"-",RANK(X22,$X$6:$X$25,0)) -> 17
A23: 18 | B23: K. Magnussen | C23: Haas-Ferrari | U23: 9 | X23: =COUNTIF(D23:W23,1)*25+COUNTIF(D23:W23,2)*18+COUNTIF(D23:W23,3)*15+COUNTIF(D23:W23,4)*12+COUNTIF(D23:W23,5)*10+COUNTIF(D23:W23,6)*8+COUNTIF(D23:W23,7)*6+COUNTIF(D23:W23,8)*4+COUNTIF(D23:W23,9)*2+COUNTIF(D23:W23,10)*1 -> 2 | Y23: =IF(X23=0,"-",RANK(X23,$X$6:$X$25,0)) -> 18
A24: 19 | B24: P. Wehrlein | C24: Sauber-Ferrari | T24: 10 | X24: =COUNTIF(D24:W24,1)*25+COUNTIF(D24:W24,2)*18+COUNTIF(D24:W24,3)*15+COUNTIF(D24:W24,4)*12+COUNTIF(D24:W24,5)*10+COUNTIF(D24:W24,6)*8+COUNTIF(D24:W24,7)*6+COUNTIF(D24:W24,8)*4+COUNTIF(D24:W24,9)*2+COUNTIF(D24:W24,10)*1 -> 1 | Y24: =IF(X24=0,"-",RANK(X24,$X$6:$X$25,0)) -> 19
A25: 20 | B25: M. Ericsson | C25: Sauber-Ferrari | X25: =COUNTIF(D25:W25,1)*25+COUNTIF(D25:W25,2)*18+COUNTIF(D25:W25,3)*15+COUNTIF(D25:W25,4)*12+COUNTIF(D25:W25,5)*10+COUNTIF(D25:W25,6)*8+COUNTIF(D25:W25,7)*6+COUNTIF(D25:W25,8)*4+COUNTIF(D25:W25,9)*2+COUNTIF(D25:W25,10)*1 -> 0 | Y25: =IF(X25=0,"-",RANK(X25,$X$6:$X$25,0)) -> -

Sheet 🎯 Anforderungen
A1: 🎯 ANFORDERUNGEN — McLAREN-HONDA 2017 — SABANOV (33) — VOM SCHNELLSTEN INS LANGSAMSTE
A2: Zweifacher Weltmeister (2014, 2015), Vize 2016 nach Motorschaden in Sepang und gehorsamem Finale in Abu Dhabi. Dann der Schock: Du verlässt Mercedes — das schnellste Auto im Feld — für McLaren-Honda, Vertrag bis mindestens 2021. Im Sky-Interview: Dank an die Mechaniker, 'Lewis' beim Vornamen, Versöhnung in Monaco, Abendessen mit Lauda in Graz. Und ein Satz, der jetzt an der Wand in Woking hängt: 'ICH werde einen Sieg einfahren!' Das Problem: Der Honda-Motor ist der schwächste und unzuverlässigste im Feld. Neues Breitbau-Reglement, mehr Abtrieb, mehr Grip — und hinten ein Antrieb, der kaum eine Renndistanz hält. Teamkollege ist Rookie Stoffel Vandoorne, nachdem Räikkönen aufgehört hat. Bottas sitzt in deinem alten Auto und will dir 'adäquat' beweisen. Die Welt schaut zu, ob ein Weltmeister im Mittelfeld die Nerven behält.
A4: ⚠️ PFLICHT — Den Weltmeister nicht beschädigen
A5: # | B5: Ziel | C5: Schwelle | D5: Aktuell | E5: Status
A6: 1 | B6: Q-Duell vs Vandoorne | C6: ≥ 14 von 20 | D6: ='📋 Quali & Notizen'!E42 -> 18 | E6: =IF(D6>=14,"✓ ERFÜLLT","✗ OFFEN") -> ✓ ERFÜLLT
A7: 2 | B7: Punkte | C7: ≥ 10 | D7: ='🏁 Fahrerwertung'!X7 -> 37 | E7: =IF(D7>=10,"✓ ERFÜLLT","✗ OFFEN") -> ✓ ERFÜLLT
A8: 3 | B8: Punkteplätze (Top-10) | C8: ≥ 4 | D8: ='📋 Quali & Notizen'!E34 -> 7 | E8: =IF(D8>=4,"✓ ERFÜLLT","✗ OFFEN") -> ✓ ERFÜLLT
A9: 4 | B9: Bestes Rennergebnis | C9: ≤ P8 | D9: ='📋 Quali & Notizen'!E37 -> 3 | E9: =IF(ISNUMBER(D9),IF(D9<=8,"✓ ERFÜLLT","✗ OFFEN"),"—") -> ✓ ERFÜLLT
A10: 5 | B10: Top-10 Quali | C10: ≥ 6 von 20 | D10: ='📋 Quali & Notizen'!E38 -> 10 | E10: =IF(D10>=6,"✓ ERFÜLLT","✗ OFFEN") -> ✓ ERFÜLLT
A11: 6 | B11: Beendete Rennen | C11: ≥ 12 von 20 | D11: ='📋 Quali & Notizen'!E30 -> 15 | E11: =IF(D11>=12,"✓ ERFÜLLT","✗ OFFEN") -> ✓ ERFÜLLT
A12: 7 | B12: Eigen-DNFs | C12: ≤ 1 | D12: ='📋 Quali & Notizen'!E32 -> 0 | E12: =IF(D12<=1,"✓ ERFÜLLT","✗ OFFEN") -> ✓ ERFÜLLT
A13: 8 | B13: Ø Quali-Position | C13: ≤ 13.0 | D13: =IFERROR('📋 Quali & Notizen'!E40,"—") -> 10.74 | E13: =IF(ISNUMBER(D13),IF(D13<=13,"✓ ERFÜLLT","✗ OFFEN"),"—") -> ✓ ERFÜLLT
A14: ⚠️ PFLICHT-STATUS | E14: =COUNTIF(E6:E13,"✓ ERFÜLLT")&" / 8 erfüllt" -> 8 / 8 erfüllt
A15: ⚠ Pflicht-Verfehlung: Ein Rookie hält mit, kaum Punkte, Fehler aus Frust. Dann heißt es: Ohne den Mercedes ist er ein Mittelfeldfahrer — genau das, was Hamilton immer gesagt hat.
A17: ✦ BONUS — Honda zum Laufen bringen
A18: # | B18: Ziel | C18: Schwelle | D18: Aktuell | E18: Status
A19: 1 | B19: Q-Duell vs Vandoorne | C19: ≥ 16 von 20 | D19: ='📋 Quali & Notizen'!E42 -> 18 | E19: =IF(D19>=16,"✓ ERFÜLLT","✗ OFFEN") -> ✓ ERFÜLLT
A20: 2 | B20: Punkte | C20: ≥ 25 | D20: ='🏁 Fahrerwertung'!X7 -> 37 | E20: =IF(D20>=25,"✓ ERFÜLLT","✗ OFFEN") -> ✓ ERFÜLLT
A21: 3 | B21: Punkteplätze (Top-10) | C21: ≥ 7 | D21: ='📋 Quali & Notizen'!E34 -> 7 | E21: =IF(D21>=7,"✓ ERFÜLLT","✗ OFFEN") -> ✓ ERFÜLLT
A22: 4 | B22: Bestes Rennergebnis | C22: ≤ P6 | D22: ='📋 Quali & Notizen'!E37 -> 3 | E22: =IF(ISNUMBER(D22),IF(D22<=6,"✓ ERFÜLLT","✗ OFFEN"),"—") -> ✓ ERFÜLLT
A23: 5 | B23: Top-10 Quali | C23: ≥ 10 von 20 | D23: ='📋 Quali & Notizen'!E38 -> 10 | E23: =IF(D23>=10,"✓ ERFÜLLT","✗ OFFEN") -> ✓ ERFÜLLT
A24: 6 | B24: Ø Quali-Position | C24: ≤ 11.0 | D24: =IFERROR('📋 Quali & Notizen'!E40,"—") -> 10.74 | E24: =IF(ISNUMBER(D24),IF(D24<=11,"✓ ERFÜLLT","✗ OFFEN"),"—") -> ✓ ERFÜLLT
A25: 7 | B25: Beendete Rennen | C25: ≥ 14 von 20 | D25: ='📋 Quali & Notizen'!E30 -> 15 | E25: =IF(D25>=14,"✓ ERFÜLLT","✗ OFFEN") -> ✓ ERFÜLLT
A26: 8 | B26: Eigen-DNFs | C26: 0 | D26: ='📋 Quali & Notizen'!E32 -> 0 | E26: =IF(D26<=0,"✓ ERFÜLLT","✗ OFFEN") -> ✓ ERFÜLLT
A27: 9 | B27: WM-Position | C27: ≤ 12 | D27: ='🏁 Fahrerwertung'!Y7 -> 13 | E27: =IF(ISNUMBER(D27),IF(D27<=12,"✓ ERFÜLLT","✗ OFFEN"),"—") -> ✗ OFFEN
A28: ✦ BONUS-STATUS | E28: =COUNTIF(E19:E27,"✓ ERFÜLLT")&" / 9 erfüllt" -> 8 / 9 erfüllt
A29: ✦ Bonus erfüllt: Regelmäßig Punkte im schlechtesten Antrieb des Feldes. Dann weiß Zak Brown, dass er den richtigen Mann geholt hat — und Honda weiß, wer ihren Motor gerade schöner fährt, als er ist.
A31: 👑 KRÖNUNG — Das Unmögliche
A32: # | B32: Ziel | C32: Schwelle | D32: Aktuell | E32: Status
A33: 1 | B33: Podien (Top-3) | C33: ≥ 1 | D33: ='📋 Quali & Notizen'!E35 -> 1 | E33: =IF(D33>=1,"✓ ERFÜLLT","✗ OFFEN") -> ✓ ERFÜLLT
A34: 2 | B34: Punkte | C34: ≥ 50 | D34: ='🏁 Fahrerwertung'!X7 -> 37 | E34: =IF(D34>=50,"✓ ERFÜLLT","✗ OFFEN") -> ✗ OFFEN
A35: 3 | B35: Punkteplätze (Top-10) | C35: ≥ 10 | D35: ='📋 Quali & Notizen'!E34 -> 7 | E35: =IF(D35>=10,"✓ ERFÜLLT","✗ OFFEN") -> ✗ OFFEN
A36: 4 | B36: Q-Duell vs Vandoorne | C36: ≥ 18 von 20 | D36: ='📋 Quali & Notizen'!E42 -> 18 | E36: =IF(D36>=18,"✓ ERFÜLLT","✗ OFFEN") -> ✓ ERFÜLLT
A37: 5 | B37: Top-10 Quali | C37: ≥ 14 von 20 | D37: ='📋 Quali & Notizen'!E38 -> 10 | E37: =IF(D37>=14,"✓ ERFÜLLT","✗ OFFEN") -> ✗ OFFEN
A38: 6 | B38: Ø Quali-Position | C38: ≤ 9.5 | D38: =IFERROR('📋 Quali & Notizen'!E40,"—") -> 10.74 | E38: =IF(ISNUMBER(D38),IF(D38<=9.5,"✓ ERFÜLLT","✗ OFFEN"),"—") -> ✗ OFFEN
A39: 7 | B39: Beendete Rennen | C39: ≥ 16 von 20 | D39: ='📋 Quali & Notizen'!E30 -> 15 | E39: =IF(D39>=16,"✓ ERFÜLLT","✗ OFFEN") -> ✗ OFFEN
A40: 8 | B40: Eigen-DNFs | C40: 0 | D40: ='📋 Quali & Notizen'!E32 -> 0 | E40: =IF(D40<=0,"✓ ERFÜLLT","✗ OFFEN") -> ✓ ERFÜLLT
A41: 9 | B41: WM-Position | C41: ≤ 9 | D41: ='🏁 Fahrerwertung'!Y7 -> 13 | E41: =IF(ISNUMBER(D41),IF(D41<=9,"✓ ERFÜLLT","✗ OFFEN"),"—") -> ✗ OFFEN
A42: 👑 KRÖNUNG-STATUS | E42: =COUNTIF(E33:E41,"✓ ERFÜLLT")&" / 9 erfüllt" -> 3 / 9 erfüllt
A43: 👑 Krönung erfüllt: Ein Podium im McLaren-Honda 2017. Dann war der Wechsel kein Fehler, sondern die Ansage, dass Weltmeister Autos schneller machen — nicht umgekehrt.
...

Sheet 🏗️ Konstrukteurs
A1: 🏗️ 2017 — KONSTRUKTEURSWERTUNG
A4: # | B4: Team | C4: Fahrer 1 | D4: Fahrer 2 | E4: Punkte | F4: Pos
A5: 1 | B5: McLaren-Honda | C5: S. Vandoorne | D5: SABANOV | E5: =SUMIF('🏁 Fahrerwertung'!$C$6:$C$25,B5,'🏁 Fahrerwertung'!$X$6:$X$25) -> 55 | F5: =IF(E5=0,"-",RANK(E5,$E$5:$E$14,0)) -> 7
A6: 2 | B6: Mercedes | C6: L. Hamilton | D6: V. Bottas | E6: =SUMIF('🏁 Fahrerwertung'!$C$6:$C$25,B6,'🏁 Fahrerwertung'!$X$6:$X$25) -> 562 | F6: =IF(E6=0,"-",RANK(E6,$E$5:$E$14,0)) -> 2
A7: 3 | B7: Ferrari | C7: S. Vettel | D7: F. Alonso | E7: =SUMIF('🏁 Fahrerwertung'!$C$6:$C$25,B7,'🏁 Fahrerwertung'!$X$6:$X$25) -> 655 | F7: =IF(E7=0,"-",RANK(E7,$E$5:$E$14,0)) -> 1
A8: 4 | B8: Red Bull-TAG Heuer | C8: D. Ricciardo | D8: M. Verstappen | E8: =SUMIF('🏁 Fahrerwertung'!$C$6:$C$25,B8,'🏁 Fahrerwertung'!$X$6:$X$25) -> 344 | F8: =IF(E8=0,"-",RANK(E8,$E$5:$E$14,0)) -> 3
A9: 5 | B9: Force India-Mercedes | C9: S. Pérez | D9: E. Ocon | E9: =SUMIF('🏁 Fahrerwertung'!$C$6:$C$25,B9,'🏁 Fahrerwertung'!$X$6:$X$25) -> 149 | F9: =IF(E9=0,"-",RANK(E9,$E$5:$E$14,0)) -> 4
A10: 6 | B10: Williams-Mercedes | C10: F. Massa | D10: L. Stroll | E10: =SUMIF('🏁 Fahrerwertung'!$C$6:$C$25,B10,'🏁 Fahrerwertung'!$X$6:$X$25) -> 125 | F10: =IF(E10=0,"-",RANK(E10,$E$5:$E$14,0)) -> 5
A11: 7 | B11: Renault | C11: N. Hülkenberg | D11: N. Rosberg | E11: =SUMIF('🏁 Fahrerwertung'!$C$6:$C$25,B11,'🏁 Fahrerwertung'!$X$6:$X$25) -> 106 | F11: =IF(E11=0,"-",RANK(E11,$E$5:$E$14,0)) -> 6
A12: 8 | B12: Toro Rosso-Renault | C12: C. Sainz | D12: D. Kvyat | E12: =SUMIF('🏁 Fahrerwertung'!$C$6:$C$25,B12,'🏁 Fahrerwertung'!$X$6:$X$25) -> 44 | F12: =IF(E12=0,"-",RANK(E12,$E$5:$E$14,0)) -> 8
A13: 9 | B13: Haas-Ferrari | C13: R. Grosjean | D13: K. Magnussen | E13: =SUMIF('🏁 Fahrerwertung'!$C$6:$C$25,B13,'🏁 Fahrerwertung'!$X$6:$X$25) -> 6 | F13: =IF(E13=0,"-",RANK(E13,$E$5:$E$14,0)) -> 9
A14: 10 | B14: Sauber-Ferrari | C14: P. Wehrlein | D14: M. Ericsson | E14: =SUMIF('🏁 Fahrerwertung'!$C$6:$C$25,B14,'🏁 Fahrerwertung'!$X$6:$X$25) -> 1 | F14: =IF(E14=0,"-",RANK(E14,$E$5:$E$14,0)) -> 10

Sheet 📋 Quali & Notizen
A1: 📋 2017 — QUALI & RENN-NOTIZEN
A2: Quali, Wetter, DNF-Grund, Eigen-Verschulden, Vandoorne-Quali, Notiz (inkl. INTERVIEWS & Zweikämpfe). 20 Rennen.
A4: Rennen | B4: Land | C4: Strecke | D4: Quali | E4: Renn-Pos | F4: Wetter | G4: Pole? | H4: DNF-Grund | I4: Eigen? | J4: Vandoorne Q | K4: Q-Duell | L4: Notiz / Schlagzeile / Interview
A5: R1 | B5: Australien | C5: Melbourne | D5: 14 | E5: =IF('🏁 Fahrerwertung'!D7="","",'🏁 Fahrerwertung'!D7) -> 8 | G5: =IF(D5=1,"★","—") -> — | J5: 17 | K5: =IF(AND(ISNUMBER(D5),ISNUMBER(J5)),IF(D5<J5,"SABANOV",IF(D5>J5,"VANDOORNE","Tie")),"") -> SABANOV | L5: "SABANOV INTO Q2… WITH HELP OF HAMILTON? He gives him a Big Tow!"
A6: R2 | B6: China | C6: Shanghai | D6: 12 | E6: =IF('🏁 Fahrerwertung'!E7="","",'🏁 Fahrerwertung'!E7) -> 6 | G6: =IF(D6=1,"★","—") -> — | J6: 17 | K6: =IF(AND(ISNUMBER(D6),ISNUMBER(J6)),IF(D6<J6,"SABANOV",IF(D6>J6,"VANDOORNE","Tie")),"") -> SABANOV | L6: "Sabanov congratulates Hamilton in Media interview for the win in Shanghai"
A7: R3 | B7: Bahrain | C7: Bahrain | D7: 12 | E7: =IF('🏁 Fahrerwertung'!F7="","",'🏁 Fahrerwertung'!F7) -> 11 | G7: =IF(D7=1,"★","—") -> — | J7: 16 | K7: =IF(AND(ISNUMBER(D7),ISNUMBER(J7)),IF(D7<J7,"SABANOV",IF(D7>J7,"VANDOORNE","Tie")),"") -> SABANOV
A8: R4 | B8: Russland | C8: Valencia | D8: 14 | E8: =IF('🏁 Fahrerwertung'!G7="","",'🏁 Fahrerwertung'!G7) -> DNF | G8: =IF(D8=1,"★","—") -> — | H8: Motor | J8: 19 | K8: =IF(AND(ISNUMBER(D8),ISNUMBER(J8)),IF(D8<J8,"SABANOV",IF(D8>J8,"VANDOORNE","Tie")),"") -> SABANOV
A9: R5 | B9: Spanien | C9: Barcelona | D9: 9 | E9: =IF('🏁 Fahrerwertung'!H7="","",'🏁 Fahrerwertung'!H7) -> 10 | G9: =IF(D9=1,"★","—") -> — | J9: 13 | K9: =IF(AND(ISNUMBER(D9),ISNUMBER(J9)),IF(D9<J9,"SABANOV",IF(D9>J9,"VANDOORNE","Tie")),"") -> SABANOV | L9: "Sabanov gets into Q3 for the first time with McLaren. And a 1 point finish in P10 in the end!"
A10: R6 | B10: Monaco | C10: Zandvoort | D10: 9 | E10: =IF('🏁 Fahrerwertung'!I7="","",'🏁 Fahrerwertung'!I7) -> 7 | G10: =IF(D10=1,"★","—") -> — | J10: 17 | K10: =IF(AND(ISNUMBER(D10),ISNUMBER(J10)),IF(D10<J10,"SABANOV",IF(D10>J10,"VANDOORNE","Tie")),"") -> SABANOV | L10: "Sabanov into Q3 and into the Points at Monaco for McLaren."
A11: R7 | B11: Aserbaidschan | C11: Fuji | D11: 12 | E11: =IF('🏁 Fahrerwertung'!J7="","",'🏁 Fahrerwertung'!J7) -> DNF | G11: =IF(D11=1,"★","—") -> — | H11: Motor | J11: 15 | K11: =IF(AND(ISNUMBER(D11),ISNUMBER(J11)),IF(D11<J11,"SABANOV",IF(D11>J11,"VANDOORNE","Tie")),"") -> SABANOV | L11: "Vandoorne with Points in Baku! Sabanov out again with engine failure"
A12: R8 | B12: Kanada | C12: Montreal | D12: 14 | E12: =IF('🏁 Fahrerwertung'!K7="","",'🏁 Fahrerwertung'!K7) -> 15 | G12: =IF(D12=1,"★","—") -> — | J12: 16 | K12: =IF(AND(ISNUMBER(D12),ISNUMBER(J12)),IF(D12<J12,"SABANOV",IF(D12>J12,"VANDOORNE","Tie")),"") -> SABANOV
A13: R9 | B13: Österreich | C13: Spielberg | D13: 10 | E13: =IF('🏁 Fahrerwertung'!L7="","",'🏁 Fahrerwertung'!L7) -> 10 | G13: =IF(D13=1,"★","—") -> — | J13: 12 | K13: =IF(AND(ISNUMBER(D13),ISNUMBER(J13)),IF(D13<J13,"SABANOV",IF(D13>J13,"VANDOORNE","Tie")),"") -> SABANOV
A14: R10 | B14: Großbritannien | C14: Silverstone | D14: DNQ | E14: =IF('🏁 Fahrerwertung'!M7="","",'🏁 Fahrerwertung'!M7) -> 14 | G14: =IF(D14=1,"★","—") -> — | J14: 15 | K14: VANDOORNE | L14: "Sabanov cant Qualify due to Engine problems, but is permitted to start on Sunday and gets good Positions"
A15: R11 | B15: Ungarn | C15: Hungaroring | D15: 4 | E15: =IF('🏁 Fahrerwertung'!N7="","",'🏁 Fahrerwertung'!N7) -> 9 | G15: =IF(D15=1,"★","—") -> — | J15: 14 | K15: =IF(AND(ISNUMBER(D15),ISNUMBER(J15)),IF(D15<J15,"SABANOV",IF(D15>J15,"VANDOORNE","Tie")),"") -> SABANOV | L15: "SABANOV WITH A BRILLIANT AND PERFECT QUALIFYING LAP IN HUNGARY! INCREDIBLE!"
A16: R12 | B16: Belgien | C16: Spa | D16: 12 | E16: =IF('🏁 Fahrerwertung'!O7="","",'🏁 Fahrerwertung'!O7) -> 11 | G16: =IF(D16=1,"★","—") -> — | J16: 14 | K16: =IF(AND(ISNUMBER(D16),ISNUMBER(J16)),IF(D16<J16,"SABANOV",IF(D16>J16,"VANDOORNE","Tie")),"") -> SABANOV
A17: R13 | B17: Italien | C17: Monza | D17: 17 | E17: =IF('🏁 Fahrerwertung'!P7="","",'🏁 Fahrerwertung'!P7) -> 16 | G17: =IF(D17=1,"★","—") -> — | J17: 19 | K17: =IF(AND(ISNUMBER(D17),ISNUMBER(J17)),IF(D17<J17,"SABANOV",IF(D17>J17,"VANDOORNE","Tie")),"") -> SABANOV
A18: R14 | B18: Singapur (Nacht) | C18: Singapur | D18: 1 | E18: =IF('🏁 Fahrerwertung'!Q7="","",'🏁 Fahrerwertung'!Q7) -> 3 | G18: =IF(D18=1,"★","—") -> ★ | J18: 14 | K18: =IF(AND(ISNUMBER(D18),ISNUMBER(J18)),IF(D18<J18,"SABANOV",IF(D18>J18,"VANDOORNE","Tie")),"") -> SABANOV | L18: "SABANOV DOES THE IMPOSSIBLE! RAIN POLE IN SINGAPORE! AHEAD OF EVERYONE ELSE!!!!!! AND GFTS FIRST MCLAREN PODIUM! THIS IS WHAT HE PROMISED!"
A19: R15 | B19: Malaysia | C19: Mugello | D19: 10 | E19: =IF('🏁 Fahrerwertung'!R7="","",'🏁 Fahrerwertung'!R7) -> DNF | G19: =IF(D19=1,"★","—") -> — | H19: Motor | J19: 15 | K19: =IF(AND(ISNUMBER(D19),ISNUMBER(J19)),IF(D19<J19,"SABANOV",IF(D19>J19,"VANDOORNE","Tie")),"") -> SABANOV
A20: R16 | B20: Japan | C20: Suzuka | D20: 9 | E20: =IF('🏁 Fahrerwertung'!S7="","",'🏁 Fahrerwertung'!S7) -> 11 | G20: =IF(D20=1,"★","—") -> — | J20: 16 | K20: =IF(AND(ISNUMBER(D20),ISNUMBER(J20)),IF(D20<J20,"SABANOV",IF(D20>J20,"VANDOORNE","Tie")),"") -> SABANOV
A21: R17 | B21: USA (Austin) | C21: COTA | D21: 10 | E21: =IF('🏁 Fahrerwertung'!T7="","",'🏁 Fahrerwertung'!T7) -> DNF | G21: =IF(D21=1,"★","—") -> — | H21: Motor | J21: 13 | K21: =IF(AND(ISNUMBER(D21),ISNUMBER(J21)),IF(D21<J21,"SABANOV",IF(D21>J21,"VANDOORNE","Tie")),"") -> SABANOV
A22: R18 | B22: Mexiko | C22: Mexico | D22: 9 | E22: =IF('🏁 Fahrerwertung'!U7="","",'🏁 Fahrerwertung'!U7) -> 13 | G22: =IF(D22=1,"★","—") -> — | J22: 17 | K22: =IF(AND(ISNUMBER(D22),ISNUMBER(J22)),IF(D22<J22,"SABANOV",IF(D22>J22,"VANDOORNE","Tie")),"") -> SABANOV
A23: R19 | B23: Brasilien | C23: Interlagos | D23: 16 | E23: =IF('🏁 Fahrerwertung'!V7="","",'🏁 Fahrerwertung'!V7) -> 12 | G23: =IF(D23=1,"★","—") -> — | J23: 13 | K23: =IF(AND(ISNUMBER(D23),ISNUMBER(J23)),IF(D23<J23,"SABANOV",IF(D23>J23,"VANDOORNE","Tie")),"") -> VANDOORNE | L23: "vandoorne beats Sabanov for 2nd time in Qualifying"
A24: R20 | B24: Abu Dhabi (Finale) | C24: Indianapolis | D24: 10 | E24: =IF('🏁 Fahrerwertung'!W7="","",'🏁 Fahrerwertung'!W7) -> DNF | G24: =IF(D24=1,"★","—") -> — | H24: Motor | J24: 14 | K24: =IF(AND(ISNUMBER(D24),ISNUMBER(J24)),IF(D24<J24,"SABANOV",IF(D24>J24,"VANDOORNE","Tie")),"") -> SABANOV | L24: "Sabanov Ends 2017 on Q3… Alonso World Champion! Retires! Ferrari bring Rosberg as Second driver into Ferrari!"
A26: 📊 SAISON-BILANZ (auto)
B28: Punkte gesamt | E28: =IFERROR('🏁 Fahrerwertung'!X7,0) -> 37
B29: WM-Position | E29: =IFERROR('🏁 Fahrerwertung'!Y7,"—") -> 13
B30: Beendete Rennen | E30: =COUNT('🏁 Fahrerwertung'!D7:W7) -> 15
B31: DNFs | E31: =20-E30 -> 5
B32: davon Eigen-DNFs | E32: =COUNTIF(I5:I24,"Y") -> 0
B33: davon Technik/Fremd | E33: =E31-E32 -> 5
B34: Punkteplätze (Top-10) | E34: =COUNTIF('🏁 Fahrerwertung'!D7:W7,"<=10") -> 7
B35: Podien (Top-3) | E35: =COUNTIF('🏁 Fahrerwertung'!D7:W7,"<=3") -> 1
B36: Siege | E36: =COUNTIF('🏁 Fahrerwertung'!D7:W7,1) -> 0
B37: Bestes Rennergebnis | E37: =IFERROR(MIN('🏁 Fahrerwertung'!D7:W7),"—") -> 3
B38: Top-10 Quali | E38: =COUNTIF(D5:D24,"<=10") -> 10
B39: Bestes Quali-Ergebnis | E39: =IFERROR(MIN(D5:D24),"—") -> 1
B40: Ø Quali SABANOV | E40: =IFERROR(ROUND(AVERAGE(D5:D24),2),"—") -> 10.74
B41: Ø Quali VANDOORNE | E41: =IFERROR(ROUND(AVERAGE(J5:J24),2),"—") -> 15.3
B42: Q-Duell — SABANOV-Siege | E42: =COUNTIF(K5:K24,"SABANOV") -> 18
B43: Q-Duell — VANDOORNE-Siege | E43: =COUNTIF(K5:K24,"VANDOORNE") -> 2
...
